<?xml version="1.0"?>
<!-- DO NOT EDIT: Generated from nxp_drone.sdf.jinja -->
<sdf version='1.6'>
  <model name='mantis'>
    <pose>0 0 0 0 0 0</pose>
    <self_collide>false</self_collide>
    <static>false</static>
    <link name="base_link">
      <inertial>
        <mass>0.559</mass>
        <inertia>
          <ixx>0.0013218</ixx>
          <iyy>0.00083023</iyy>
          <izz>0.0013443</izz>
          <!--<ixx>0.004125</ixx>
          <iyy>0.004125</iyy>
          <izz>0.005225</izz>-->

        </inertia>
      </inertial>
      <gravity>true</gravity>
      <self_collide>false</self_collide>
      <velocity_decay/>
      <visual name="base_link_visual">
        <pose>0 0 .025 0 0 0</pose>
        <geometry>
          <mesh>
            <scale>1 1 1</scale>
            <uri>model://mantis/meshes/base_link_new.dae</uri>
          </mesh>
        </geometry>
        <material>
          <script>
            <name>Gazebo/Black</name>
            <uri>file://media/materials/scripts/gazebo.material</uri>
          </script>
        </material>
      </visual>
      
      <collision name="base_link_collision_0">
        <pose>0 0 .007 0 0 0</pose>
        <geometry>
          <box>
            <size>0.20 0.20 0.05</size>
          </box>
        </geometry>
        <surface>
          <contact>
            <ode>
              <min_depth>0.001</min_depth>
              <max_vel>0</max_vel>
            </ode>
          </contact>
          <friction>
            <ode/>
          </friction>
        </surface>
      </collision>
      <!--
      <collision name="base_link_collision_1">
        <pose>0 -0.098 -.123 -0.35 0 0</pose>
        <geometry>
          <box>
            <size>0.015 0.015 0.21</size>
          </box>
        </geometry>
        <surface>
          <contact>
            <ode>
              <min_depth>0.001</min_depth>
              <max_vel>0</max_vel>
            </ode>
          </contact>
          <friction>
            <ode/>
          </friction>
        </surface>
      </collision>
      <collision name="base_link_collision_2">
        <pose>0 0.098 -.123 0.35 0 0</pose>
        <geometry>
          <box>
            <size>0.015 0.015 0.21</size>
          </box>
        </geometry>
        <surface>
          <contact>
            <ode>
              <min_depth>0.001</min_depth>
              <max_vel>0</max_vel>
            </ode>
          </contact>
          <friction>
            <ode/>
          </friction>
        </surface>
      </collision>
      <collision name="base_link_collision_3">
        <pose>0 -0.132 -.2195 0 0 0</pose>
        <geometry>
          <box>
            <size>0.25 0.015 0.015</size>
          </box>
        </geometry>
        <surface>
          <contact>
            <ode>
              <min_depth>0.001</min_depth>
              <max_vel>0</max_vel>
            </ode>
          </contact>
          <friction>
            <ode/>
          </friction>
        </surface>
      </collision>
      <collision name="base_link_collision_4">
        <pose>0 0.132 -.2195 0 0 0</pose>
        <geometry>
          <box>
            <size>0.25 0.015 0.015</size>
          </box>
        </geometry>
        <surface>
          <contact>
            <ode>
              <min_depth>0.001</min_depth>
              <max_vel>0</max_vel>
            </ode>
          </contact>
          <friction>
            <ode/>
          </friction>
        </surface>
      </collision>
          -->

    </link>
    <link name='/imu_link'>
      <pose>0 0 0 0 0 0</pose>
      <inertial>
        <pose>0 0 0 0 0 0</pose>
        <mass>0.015</mass>
        <inertia>
          <ixx>1e-05</ixx>
          <ixy>0</ixy>
          <ixz>0</ixz>
          <iyy>1e-05</iyy>
          <iyz>0</iyz>
          <izz>1e-05</izz>
        </inertia>
      </inertial>
    </link>
    <joint name='imu_nxp_drone_joint' type='revolute'>
      <child>/imu_link</child>
      <parent>base_link</parent>
      <axis>
        <xyz>1 0 0</xyz>
        <limit>
          <lower>0</lower>
          <upper>0</upper>
          <effort>0</effort>
          <velocity>0</velocity>
        </limit>
        <dynamics>
          <spring_reference>0</spring_reference>
          <spring_stiffness>0</spring_stiffness>
        </dynamics>
        <use_parent_model_frame>1</use_parent_model_frame>
      </axis>
    </joint>

    
      
      
      
      

      
        
        
        
      

      

    <!--Rotor 0 -->
    <link name="rotor_0">
      <gravity>true</gravity>
      <self_collide>false</self_collide>
      <velocity_decay/>
      <pose>0.06 -0.06 0.0 0 0 0</pose>
      <inertial>
          <mass>0.011076923076923075</mass>
          <inertia>
            <ixx>3.8464910483993325e-010</ixx>
            <iyy>2.6115851691700804e-010</iyy>
            <izz>2.649858234714004e-010</izz>
          </inertia>
        </inertial>
      <visual name="rotor_0_visual">
        <pose>-0.01 -0.06653846153 -0.00909090909 0 0 0</pose>
        <geometry>
          <mesh>
            <scale>0.38461538461 0.38461538461 0.38461538461</scale>
            <uri>model://mantis/meshes/1345_prop_ccw.stl</uri>
          </mesh>
        </geometry>
        <material>
          <script>
            <name>Gazebo/Black</name>
            <uri>file://media/materials/scripts/gazebo.material</uri>
          </script>
        </material>
      </visual>
      <!--<visual name="rotor_0_visual_motor_top">
        <pose>-.025 -.025 -0.042 0 0 0</pose>
        <geometry>
          <mesh>
            <scale>1 1 1</scale>
            <uri>model://nxp_drone/meshes/5010Top.stl</uri>
          </mesh>
        </geometry>
        <material>
          <script>
            <name>Gazebo/Grey</name>
            <uri>file://media/materials/scripts/gazebo.material</uri>
          </script>
        </material>
      </visual>
      <visual name="rotor_0_visual_motor_bottom">
        <pose>0 0 -0.024 0 0 0</pose>
        <geometry>
          <cylinder>
            <radius>0.025</radius>
            <length>0.01</length>
          </cylinder>
        </geometry>
        <material>
          <script>
            <name>Gazebo/Black</name>
            <uri>file://media/materials/scripts/gazebo.material</uri>
          </script>
        </material>
      </visual>-->
      <collision name="rotor_0_collision">
        <pose>0 0 0 0 0 0 </pose>
        <geometry>
          <box>
            <size>0.07 0.01 0.0008461538461538462</size>
          </box>
        </geometry>
        <surface>
          <contact>
            <ode>
              <min_depth>0.001</min_depth>
              <max_vel>0</max_vel>
            </ode>
          </contact>
          <friction>
            <ode/>
          </friction>
        </surface>
      </collision>
    </link>
    <joint name="rotor_0_joint" type="revolute">
      <parent>base_link</parent>
      <child>rotor_0</child>
      <axis>
        <xyz>0 0 1</xyz>
        <limit>
          <lower>-1e+16</lower>
          <upper>1e+16</upper>
        </limit>
        <dynamics>
          <spring_reference>0</spring_reference>
          <spring_stiffness>0</spring_stiffness>
        </dynamics>
        <use_parent_model_frame>1</use_parent_model_frame>
      </axis>
    </joint>
    <plugin name='rotor_0_motor_model' filename='libgazebo_motor_model.so'>
      <robotNamespace></robotNamespace>
      <jointName>rotor_0_joint</jointName>
      <linkName>rotor_0</linkName>
      <turningDirection>ccw</turningDirection>
      <timeConstantUp>0.0125</timeConstantUp>
      <timeConstantDown>0.025</timeConstantDown>
      <maxRotVelocity>3300</maxRotVelocity>
      <motorConstant>0.000000391</motorConstant>
      <momentConstant>0.0031830988618379067</momentConstant>
      <commandSubTopic>/gazebo/command/motor_speed</commandSubTopic>
      <motorNumber>0</motorNumber>
      <rotorDragCoefficient>0.00044924986055284316</rotorDragCoefficient>
      <rollingMomentCoefficient>1e-06</rollingMomentCoefficient>
      <motorSpeedPubTopic>/motor_speed/0</motorSpeedPubTopic>
      <rotorVelocitySlowdownSim>10</rotorVelocitySlowdownSim>
    </plugin>
    
      
      
      
      

      
        
        
        
      

      

    <!--Rotor 1 -->
    <link name="rotor_1">
      <gravity>true</gravity>
      <self_collide>false</self_collide>
      <velocity_decay/>
      <pose>-0.06 0.06 0.0 0 0 0</pose>
      <inertial>
          <mass>0.011076923076923075</mass>
          <inertia>
            <ixx>3.8464910483993325e-010</ixx>
            <iyy>2.6115851691700804e-010</iyy>
            <izz>2.649858234714004e-010</izz>
          </inertia>
        </inertial>
      <visual name="rotor_1_visual">
        <pose>-0.01 -0.06653846153 -0.00909090909 0 0 0</pose>
        <geometry>
          <mesh>
            <scale>0.38461538461 0.38461538461 0.38461538461</scale>
            <uri>model://mantis/meshes/1345_prop_ccw.stl</uri>
          </mesh>
        </geometry>
        <material>
          <script>
            <name>Gazebo/Black</name>
            <uri>file://media/materials/scripts/gazebo.material</uri>
          </script>
        </material>
      </visual>
      <!--<visual name="rotor_1_visual_motor_top">
        <pose>-.025 -.025 -0.042 0 0 0</pose>
        <geometry>
          <mesh>
            <scale>1 1 1</scale>
            <uri>model://nxp_drone/meshes/5010Top.stl</uri>
          </mesh>
        </geometry>
        <material>
          <script>
            <name>Gazebo/Grey</name>
            <uri>file://media/materials/scripts/gazebo.material</uri>
          </script>
        </material>
      </visual>-->
      <!--<visual name="rotor_1_visual_motor_bottom">
        <pose>0 0 -0.024 0 0 0</pose>
        <geometry>
          <cylinder>
            <radius>0.025</radius>
            <length>0.01</length>
          </cylinder>
        </geometry>
        <material>
          <script>
            <name>Gazebo/Black</name>
            <uri>file://media/materials/scripts/gazebo.material</uri>
          </script>
        </material>
      </visual>-->
      <collision name="rotor_1_collision">
        <pose>0 0 0 0 0 0 </pose>
        <geometry>
          <box>
            <size>0.07 0.01 0.0008461538461538462</size>
          </box>
        </geometry>
        <surface>
          <contact>
            <ode>
              <min_depth>0.001</min_depth>
              <max_vel>0</max_vel>
            </ode>
          </contact>
          <friction>
            <ode/>
          </friction>
        </surface>
      </collision>
    </link>
    <joint name="rotor_1_joint" type="revolute">
      <parent>base_link</parent>
      <child>rotor_1</child>
      <axis>
        <xyz>0 0 1</xyz>
        <limit>
          <lower>-1e+16</lower>
          <upper>1e+16</upper>
        </limit>
        <dynamics>
          <spring_reference>0</spring_reference>
          <spring_stiffness>0</spring_stiffness>
        </dynamics>
        <use_parent_model_frame>1</use_parent_model_frame>
      </axis>
    </joint>
    <plugin name='rotor_1_motor_model' filename='libgazebo_motor_model.so'>
      <robotNamespace></robotNamespace>
      <jointName>rotor_1_joint</jointName>
      <linkName>rotor_1</linkName>
      <turningDirection>ccw</turningDirection>
      <timeConstantUp>0.0125</timeConstantUp>
      <timeConstantDown>0.025</timeConstantDown>
      <maxRotVelocity>3300</maxRotVelocity>
      <motorConstant>0.000000391</motorConstant>
      <momentConstant>0.0031830988618379067</momentConstant>
      <commandSubTopic>/gazebo/command/motor_speed</commandSubTopic>
      <motorNumber>1</motorNumber>
      <rotorDragCoefficient>0.00044924986055284316</rotorDragCoefficient>
      <rollingMomentCoefficient>1e-06</rollingMomentCoefficient>
      <motorSpeedPubTopic>/motor_speed/1</motorSpeedPubTopic>
      <rotorVelocitySlowdownSim>10</rotorVelocitySlowdownSim>
    </plugin>
    
      
      
      
      

      
        
        
        
      

      

    <!--Rotor 2 -->
    <link name="rotor_2">
      <gravity>true</gravity>
      <self_collide>false</self_collide>
      <velocity_decay/>
      <pose>0.06 0.06 0.0 0 0 0</pose>
      <inertial>
          <mass>0.011076923076923075</mass>
          <inertia>
            <ixx>3.8464910483993325e-010</ixx>
            <iyy>2.6115851691700804e-010</iyy>
            <izz>2.649858234714004e-010</izz>
          </inertia>
        </inertial>
      <visual name="rotor_2_visual">
        <pose>-0.01 -0.06653846153 -0.00909090909 0 0 0</pose>
        <geometry>
          <mesh>
            <scale>0.38461538461 0.38461538461 0.38461538461</scale>
            <uri>model://mantis/meshes/1345_prop_cw.stl</uri>
          </mesh>
        </geometry>
        <material>
          <script>
            <name>Gazebo/Black</name>
            <uri>file://media/materials/scripts/gazebo.material</uri>
          </script>
        </material>
      </visual>
      <!--
      <visual name="rotor_2_visual_motor_top">
        <pose>-.025 -.025 -0.042 0 0 0</pose>
        <geometry>
          <mesh>
            <scale>1 1 1</scale>
            <uri>model://nxp_drone/meshes/5010Top.stl</uri>
          </mesh>
        </geometry>
        <material>
          <script>
            <name>Gazebo/Grey</name>
            <uri>file://media/materials/scripts/gazebo.material</uri>
          </script>
        </material>
      </visual>
      <visual name="rotor_2_visual_motor_bottom">
        <pose>0 0 -0.024 0 0 0</pose>
        <geometry>
          <cylinder>
            <radius>0.025</radius>
            <length>0.01</length>
          </cylinder>
        </geometry>
        <material>
          <script>
            <name>Gazebo/Black</name>
            <uri>file://media/materials/scripts/gazebo.material</uri>
          </script>
        </material>
      </visual>-->
      <collision name="rotor_2_collision">
        <pose>0 0 0 0 0 0 </pose>
        <geometry>
          <box>
            <size>0.07 0.01 0.0008461538461538462</size>
          </box>
        </geometry>
        <surface>
          <contact>
            <ode>
              <min_depth>0.001</min_depth>
              <max_vel>0</max_vel>
            </ode>
          </contact>
          <friction>
            <ode/>
          </friction>
        </surface>
      </collision>
    </link>
    <joint name="rotor_2_joint" type="revolute">
      <parent>base_link</parent>
      <child>rotor_2</child>
      <axis>
        <xyz>0 0 1</xyz>
        <limit>
          <lower>-1e+16</lower>
          <upper>1e+16</upper>
        </limit>
        <dynamics>
          <spring_reference>0</spring_reference>
          <spring_stiffness>0</spring_stiffness>
        </dynamics>
        <use_parent_model_frame>1</use_parent_model_frame>
      </axis>
    </joint>
    <plugin name='rotor_2_motor_model' filename='libgazebo_motor_model.so'>
      <robotNamespace></robotNamespace>
      <jointName>rotor_2_joint</jointName>
      <linkName>rotor_2</linkName>
      <turningDirection>cw</turningDirection>
      <timeConstantUp>0.0125</timeConstantUp>
      <timeConstantDown>0.025</timeConstantDown>
      <maxRotVelocity>3300</maxRotVelocity>
      <motorConstant>0.000000391</motorConstant>
      <momentConstant>0.0031830988618379067</momentConstant>
      <commandSubTopic>/gazebo/command/motor_speed</commandSubTopic>
      <motorNumber>2</motorNumber>
      <rotorDragCoefficient>0.00044924986055284316</rotorDragCoefficient>
      <rollingMomentCoefficient>1e-06</rollingMomentCoefficient>
      <motorSpeedPubTopic>/motor_speed/2</motorSpeedPubTopic>
      <rotorVelocitySlowdownSim>10</rotorVelocitySlowdownSim>
    </plugin>
    
      
      
      
      

      
        
        
        
      

      

    <!--Rotor 3 -->
    <link name="rotor_3">
      <gravity>true</gravity>
      <self_collide>false</self_collide>
      <velocity_decay/>
      <pose>-0.06 -0.06 0.0 0 0 0</pose>
      <inertial>
          <mass>0.011076923076923075</mass>
          <inertia>
            <ixx>3.8464910483993325e-010</ixx>
            <iyy>2.6115851691700804e-010</iyy>
            <izz>2.649858234714004e-010</izz>
          </inertia>
        </inertial>
      <visual name="rotor_3_visual">
        <pose>-0.01 -0.06653846153 -0.00909090909 0 0 0</pose>
        <geometry>
          <mesh>
            <scale>0.38461538461 0.38461538461 0.38461538461</scale>
            <uri>model://mantis/meshes/1345_prop_cw.stl</uri>
          </mesh>
        </geometry>
        <material>
          <script>
            <name>Gazebo/Black</name>
            <uri>file://media/materials/scripts/gazebo.material</uri>
          </script>
        </material>
      </visual>
      <!--<visual name="rotor_3_visual_motor_top">
        <pose>-.025 -.025 -0.042 0 0 0</pose>
        <geometry>
          <mesh>
            <scale>1 1 1</scale>
            <uri>model://nxp_drone/meshes/5010Top.stl</uri>
          </mesh>
        </geometry>
        <material>
          <script>
            <name>Gazebo/Grey</name>
            <uri>file://media/materials/scripts/gazebo.material</uri>
          </script>
        </material>
      </visual>
      <visual name="rotor_3_visual_motor_bottom">
        <pose>0 0 -0.024 0 0 0</pose>
        <geometry>
          <cylinder>
            <radius>0.025</radius>
            <length>0.01</length>
          </cylinder>
        </geometry>
        <material>
          <script>
            <name>Gazebo/Black</name>
            <uri>file://media/materials/scripts/gazebo.material</uri>
          </script>
        </material>
      </visual>-->
      <collision name="rotor_3_collision">
        <pose>0 0 0 0 0 0 </pose>
        <geometry>
          <box>
            <size>0.07 0.01 0.0008461538461538462</size>
          </box>
        </geometry>
        <surface>
          <contact>
            <ode>
              <min_depth>0.001</min_depth>
              <max_vel>0</max_vel>
            </ode>
          </contact>
          <friction>
            <ode/>
          </friction>
        </surface>
      </collision>
    </link>
    <joint name="rotor_3_joint" type="revolute">
      <parent>base_link</parent>
      <child>rotor_3</child>
      <axis>
        <xyz>0 0 1</xyz>
        <limit>
          <lower>-1e+16</lower>
          <upper>1e+16</upper>
        </limit>
        <dynamics>
          <spring_reference>0</spring_reference>
          <spring_stiffness>0</spring_stiffness>
        </dynamics>
        <use_parent_model_frame>1</use_parent_model_frame>
      </axis>
    </joint>
    <plugin name='rotor_3_motor_model' filename='libgazebo_motor_model.so'>
      <robotNamespace></robotNamespace>
      <jointName>rotor_3_joint</jointName>
      <linkName>rotor_3</linkName>
      <turningDirection>cw</turningDirection>
      <timeConstantUp>0.0125</timeConstantUp>
      <timeConstantDown>0.025</timeConstantDown>
      <maxRotVelocity>3300</maxRotVelocity>
      <motorConstant>0.000000391</motorConstant>
      <momentConstant>0.0031830988618379067</momentConstant>
      <commandSubTopic>/gazebo/command/motor_speed</commandSubTopic>
      <motorNumber>3</motorNumber>
      <rotorDragCoefficient>0.00044924986055284316</rotorDragCoefficient>
      <rollingMomentCoefficient>1e-06</rollingMomentCoefficient>
      <motorSpeedPubTopic>/motor_speed/3</motorSpeedPubTopic>
      <rotorVelocitySlowdownSim>10</rotorVelocitySlowdownSim>
    </plugin>
    
    <include>
      <uri>model://gps</uri>
      <pose>0 0 0 0 0 0</pose>
      <name>gps0</name>
    </include>
    <joint name='gps0_joint' type='fixed'>
      <child>gps0::link</child>
      <parent>base_link</parent>
    </joint>
    <plugin name='groundtruth_plugin' filename='libgazebo_groundtruth_plugin.so'>
      <robotNamespace/>
    </plugin>
    <plugin name='magnetometer_plugin' filename='libgazebo_magnetometer_plugin.so'>
      <robotNamespace/>
      <pubRate>100</pubRate>
      <noiseDensity>0.0004</noiseDensity>
      <!-- 6.4e-06 -->
      <randomWalk>6.4e-06</randomWalk>
      <biasCorrelationTime>600</biasCorrelationTime>
      <magTopic>/mag</magTopic>
    </plugin>
    <plugin name='barometer_plugin' filename='libgazebo_barometer_plugin.so'>
      <robotNamespace/>
      <pubRate>50</pubRate>
      <baroTopic>/baro</baroTopic>
      <baroDriftPaPerSec>0</baroDriftPaPerSec>
    </plugin>
    <plugin name='mavlink_interface' filename='libgazebo_mavlink_interface.so'>
      <robotNamespace/>
      <imuSubTopic>/imu</imuSubTopic>
      <magSubTopic>/mag</magSubTopic>
      <baroSubTopic>/baro</baroSubTopic>
      <mavlink_addr>INADDR_ANY</mavlink_addr>
      <mavlink_udp_port>14560</mavlink_udp_port>
      <mavlink_tcp_port>4560</mavlink_tcp_port>
      <serialEnabled>0</serialEnabled>
      <serialDevice>/dev/ttyACM0</serialDevice>
      <baudRate>921600</baudRate>
      <qgc_addr>INADDR_ANY</qgc_addr>
      <qgc_udp_port>14550</qgc_udp_port>
      <sdk_addr>INADDR_ANY</sdk_addr>
      <sdk_udp_port>14540</sdk_udp_port>
      <hil_mode>0</hil_mode>
      <hil_state_level>0</hil_state_level>
      <send_vision_estimation>0</send_vision_estimation>
      <send_odometry>1</send_odometry>
      <enable_lockstep>1</enable_lockstep>
      <use_tcp>1</use_tcp>
      <motorSpeedCommandPubTopic>/gazebo/command/motor_speed</motorSpeedCommandPubTopic>
      <control_channels>
        <channel name='rotor1'>
          <input_index>0</input_index>
          <input_offset>0</input_offset>
          <input_scaling>3000</input_scaling>
          <zero_position_disarmed>0</zero_position_disarmed>
          <zero_position_armed>300</zero_position_armed>
          <joint_control_type>velocity</joint_control_type>
        </channel>
        <channel name='rotor2'>
          <input_index>1</input_index>
          <input_offset>0</input_offset>
          <input_scaling>3000</input_scaling>
          <zero_position_disarmed>0</zero_position_disarmed>
          <zero_position_armed>300</zero_position_armed>
          <joint_control_type>velocity</joint_control_type>
        </channel>
        <channel name='rotor3'>
          <input_index>2</input_index>
          <input_offset>0</input_offset>
          <input_scaling>3000</input_scaling>
          <zero_position_disarmed>0</zero_position_disarmed>
          <zero_position_armed>300</zero_position_armed>
          <joint_control_type>velocity</joint_control_type>
        </channel>
        <channel name='rotor4'>
          <input_index>3</input_index>
          <input_offset>0</input_offset>
          <input_scaling>3000</input_scaling>
          <zero_position_disarmed>0</zero_position_disarmed>
          <zero_position_armed>300</zero_position_armed>
          <joint_control_type>velocity</joint_control_type>
        </channel>
      </control_channels>
    </plugin>
    <static>0</static>
    <plugin name='rotors_gazebo_imu_plugin' filename='libgazebo_imu_plugin.so'>
      <robotNamespace/>
      <linkName>/imu_link</linkName>
      <imuTopic>/imu</imuTopic>
      <!-- 0.00018665 -->
      <gyroscopeNoiseDensity>0.00018665</gyroscopeNoiseDensity>
      <!-- 3.8785e-05 -->
      <gyroscopeRandomWalk>3.8785e-05</gyroscopeRandomWalk>
      <gyroscopeBiasCorrelationTime>1000.0</gyroscopeBiasCorrelationTime>
      <gyroscopeTurnOnBiasSigma>0.0087</gyroscopeTurnOnBiasSigma>
      <!-- 0.00186, lesser is better -->
      <accelerometerNoiseDensity>0.00186</accelerometerNoiseDensity>
      <!-- 0.006 changed to 0.0006 , lesser is better-->
      <accelerometerRandomWalk>0.006</accelerometerRandomWalk>
      <!-- 300  -->
      <accelerometerBiasCorrelationTime>300.0</accelerometerBiasCorrelationTime>
      <!-- 0.196 -->
      <accelerometerTurnOnBiasSigma>0.196</accelerometerTurnOnBiasSigma>
    </plugin>
    <plugin name="p3d_base_controller" filename="libgazebo_ros_p3d.so">
      <alwaysOn>true</alwaysOn>
      <updateRate>50.0</updateRate>
      <bodyName>base_link</bodyName>
      <topicName>gazebo/ground_truth/odom</topicName>
      <gaussianNoise>0.0</gaussianNoise>
      <frameName>map</frameName>
      <xyzOffsets>0 0 -0.2</xyzOffsets>
      <rpyOffsets>0 0 0</rpyOffsets>
    </plugin>
  </model>
</sdf>